Workbook

Sheet Claims
A1: id | B1: branch | C1: category | D1: amount | E1: status | F1: submitted | G1: approved | H1: limit | I1: over_limit | J1: date_check | L1: status | M1: count
A2: CLM-0001 | B2: BR5 | C2: Property | D2: 13335 | E2: Submitted | F2: =DATE(2026,4,15) -> 46127 | H2: =VLOOKUP($C2,Limits!$A$2:$B$6,2,FALSE) -> 20000 | I2: =IF(D2>H2,"OVER","OK") -> OK | J2: =IF(G2="","OK",IF(G2<F2,"BAD_DATE","OK")) -> OK | L2: Submitted | M2: =COUNTIF($E$2:$E$301,L2) -> 83
A3: CLM-0002 | B3: BR5 | C3: Auto | D3: 19792 | E3: Rejected | F3: =DATE(2026,6,21) -> 46194 | H3: =VLOOKUP($C3,Limits!$A$2:$B$6,2,FALSE) -> 5000 | I3: =IF(D3>H3,"OVER","OK") -> OVER | J3: =IF(G3="","OK",IF(G3<F3,"BAD_DATE","OK")) -> OK | L3: Approved | M3: =COUNTIF($E$2:$E$301,L3) -> 69
A4: CLM-0003 | B4: BR3 | C4: Travel | D4: 15551 | E4: Paid | F4: =DATE(2026,2,19) -> 46072 | G4: =DATE(2026,2,39) -> 46092 | H4: =VLOOKUP($C4,Limits!$A$2:$B$6,2,FALSE) -> 3000 | I4: =IF(D4>H4,"OVER","OK") -> OVER | J4: =IF(G4="","OK",IF(G4<F4,"BAD_DATE","OK")) -> OK | L4: Rejected | M4: =COUNTIF($E$2:$E$301,L4) -> 79
A5: CLM-0004 | B5: BR5 | C5: Travel | D5: 21867 | E5: Submitted | F5: =DATE(2026,1,28) -> 46050 | H5: =VLOOKUP($C5,Limits!$A$2:$B$6,2,FALSE) -> 3000 | I5: =IF(D5>H5,"OVER","OK") -> OVER | J5: =IF(G5="","OK",IF(G5<F5,"BAD_DATE","OK")) -> OK | L5: Paid | M5: =COUNTIF($E$2:$E$301,L5) -> 69
A6: CLM-0005 | B6: BR3 | C6: Property | D6: 11328 | E6: Rejected | F6: =DATE(2026,1,26) -> 46048 | H6: =VLOOKUP($C6,Limits!$A$2:$B$6,2,FALSE) -> 20000 | I6: =IF(D6>H6,"OVER","OK") -> OK | J6: =IF(G6="","OK",IF(G6<F6,"BAD_DATE","OK")) -> OK
A7: CLM-0006 | B7: BR2 | C7: Liability | D7: 17616 | E7: Approved | F7: =DATE(2026,1,5) -> 46027 | G7: =DATE(2026,1,16) -> 46038 | H7: =VLOOKUP($C7,Limits!$A$2:$B$6,2,FALSE) -> 15000 | I7: =IF(D7>H7,"OVER","OK") -> OVER | J7: =IF(G7="","OK",IF(G7<F7,"BAD_DATE","OK")) -> OK
A8: CLM-0007 | B8: BR3 | C8: Liability | D8: 10059 | E8: Paid | F8: =DATE(2026,3,14) -> 46095 | G8: =DATE(2026,3,16) -> 46097 | H8: =VLOOKUP($C8,Limits!$A$2:$B$6,2,FALSE) -> 15000 | I8: =IF(D8>H8,"OVER","OK") -> OK | J8: =IF(G8="","OK",IF(G8<F8,"BAD_DATE","OK")) -> OK
A9: CLM-0008 | B9: BR1 | C9: Medical | D9: 1925 | E9: Rejected | F9: =DATE(2026,5,28) -> 46170 | H9: =VLOOKUP($C9,Limits!$A$2:$B$6,2,FALSE) -> 10000 | I9: =IF(D9>H9,"OVER","OK") -> OK | J9: =IF(G9="","OK",IF(G9<F9,"BAD_DATE","OK")) -> OK
A10: CLM-0009 | B10: BR3 | C10: Auto | D10: 5829 | E10: Approved | F10: =DATE(2026,2,28) -> 46081 | G10: =DATE(2026,2,32) -> 46085 | H10: =VLOOKUP($C10,Limits!$A$2:$B$6,2,FALSE) -> 5000 | I10: =IF(D10>H10,"OVER","OK") -> OVER | J10: =IF(G10="","OK",IF(G10<F10,"BAD_DATE","OK")) -> OK
A11: CLM-0010 | B11: BR1 | C11: Liability | D11: 21467 | E11: Rejected | F11: =DATE(2026,4,10) -> 46122 | H11: =VLOOKUP($C11,Limits!$A$2:$B$6,2,FALSE) -> 15000 | I11: =IF(D11>H11,"OVER","OK") -> OVER | J11: =IF(G11="","OK",IF(G11<F11,"BAD_DATE","OK")) -> OK
A12: CLM-0011 | B12: BR5 | C12: Auto | D12: 9020 | E12: Approved | F12: =DATE(2026,1,25) -> 46047 | G12: =DATE(2026,1,43) -> 46065 | H12: =VLOOKUP($C12,Limits!$A$2:$B$6,2,FALSE) -> 5000 | I12: =IF(D12>H12,"OVER","OK") -> OVER | J12: =IF(G12="","OK",IF(G12<F12,"BAD_DATE","OK")) -> OK
A13: CLM-0012 | B13: BR2 | C13: Liability | D13: 18851 | E13: Submitted | F13: =DATE(2026,5,13) -> 46155 | H13: =VLOOKUP($C13,Limits!$A$2:$B$6,2,FALSE) -> 15000 | I13: =IF(D13>H13,"OVER","OK") -> OVER | J13: =IF(G13="","OK",IF(G13<F13,"BAD_DATE","OK")) -> OK
A14: CLM-0013 | B14: BR5 | C14: Liability | D14: 19427 | E14: Paid | F14: =DATE(2026,3,15) -> 46096 | G14: =DATE(2026,3,35) -> 46116 | H14: =VLOOKUP($C14,Limits!$A$2:$B$6,2,FALSE) -> 15000 | I14: =IF(D14>H14,"OVER","OK") -> OVER | J14: =IF(G14="","OK",IF(G14<F14,"BAD_DATE","OK")) -> OK
A15: CLM-0014 | B15: BR4 | C15: Property | D15: 5226 | E15: Rejected | F15: =DATE(2026,6,23) -> 46196 | H15: =VLOOKUP($C15,Limits!$A$2:$B$6,2,FALSE) -> 20000 | I15: =IF(D15>H15,"OVER","OK") -> OK | J15: =IF(G15="","OK",IF(G15<F15,"BAD_DATE","OK")) -> OK
A16: CLM-0015 | B16: BR5 | C16: Liability | D16: 9394 | E16: Rejected | F16: =DATE(2026,6,25) -> 46198 | H16: =VLOOKUP($C16,Limits!$A$2:$B$6,2,FALSE) -> 15000 | I16: =IF(D16>H16,"OVER","OK") -> OK | J16: =IF(G16="","OK",IF(G16<F16,"BAD_DATE","OK")) -> OK
A17: CLM-0016 | B17: BR1 | C17: Liability | D17: 5769 | E17: Approved | F17: =DATE(2026,2,10) -> 46063 | G17: =DATE(2026,2,27) -> 46080 | H17: =VLOOKUP($C17,Limits!$A$2:$B$6,2,FALSE) -> 15000 | I17: =IF(D17>H17,"OVER","OK") -> OK | J17: =IF(G17="","OK",IF(G17<F17,"BAD_DATE","OK")) -> OK
A18: CLM-0017 | B18: BR5 | C18: Travel | D18: 9010 | E18: Rejected | F18: =DATE(2026,4,18) -> 46130 | H18: =VLOOKUP($C18,Limits!$A$2:$B$6,2,FALSE) -> 3000 | I18: =IF(D18>H18,"OVER","OK") -> OVER | J18: =IF(G18="","OK",IF(G18<F18,"BAD_DATE","OK")) -> OK
A19: CLM-0018 | B19: BR1 | C19: Travel | D19: 15152 | E19: Rejected | F19: =DATE(2026,6,6) -> 46179 | H19: =VLOOKUP($C19,Limits!$A$2:$B$6,2,FALSE) -> 3000 | I19: =IF(D19>H19,"OVER","OK") -> OVER | J19: =IF(G19="","OK",IF(G19<F19,"BAD_DATE","OK")) -> OK
A20: CLM-0019 | B20: BR4 | C20: Property | D20: 6655 | E20: Rejected | F20: =DATE(2026,5,22) -> 46164 | H20: =VLOOKUP($C20,Limits!$A$2:$B$6,2,FALSE) -> 20000 | I20: =IF(D20>H20,"OVER","OK") -> OK | J20: =IF(G20="","OK",IF(G20<F20,"BAD_DATE","OK")) -> OK
A21: CLM-0020 | B21: BR5 | C21: Medical | D21: 1703 | E21: Paid | F21: =DATE(2026,4,19) -> 46131 | G21: =DATE(2026,4,22) -> 46134 | H21: =VLOOKUP($C21,Limits!$A$2:$B$6,2,FALSE) -> 10000 | I21: =IF(D21>H21,"OVER","OK") -> OK | J21: =IF(G21="","OK",IF(G21<F21,"BAD_DATE","OK")) -> OK
A22: CLM-0021 | B22: BR5 | C22: Auto | D22: 20976 | E22: Approved | F22: =DATE(2026,6,12) -> 46185 | G22: =DATE(2026,6,28) -> 46201 | H22: =VLOOKUP($C22,Limits!$A$2:$B$6,2,FALSE) -> 5000 | I22: =IF(D22>H22,"OVER","OK") -> OVER | J22: =IF(G22="","OK",IF(G22<F22,"BAD_DATE","OK")) -> OK
A23: CLM-0022 | B23: BR1 | C23: Travel | D23: 13284 | E23: Approved | F23: =DATE(2026,3,13) -> 46094 | G23: =DATE(2026,3,37) -> 46118 | H23: =VLOOKUP($C23,Limits!$A$2:$B$6,2,FALSE) -> 3000 | I23: =IF(D23>H23,"OVER","OK") -> OVER | J23: =IF(G23="","OK",IF(G23<F23,"BAD_DATE","OK")) -> OK
A24: CLM-0023 | B24: BR4 | C24: Liability | D24: 17384 | E24: Submitted | F24: =DATE(2026,2,23) -> 46076 | H24: =VLOOKUP($C24,Limits!$A$2:$B$6,2,FALSE) -> 15000 | I24: =IF(D24>H24,"OVER","OK") -> OVER | J24: =IF(G24="","OK",IF(G24<F24,"BAD_DATE","OK")) -> OK
A25: CLM-0024 | B25: BR1 | C25: Property | D25: 1500 | E25: Approved | F25: =DATE(2026,2,17) -> 46070 | G25: =DATE(2026,2,19) -> 46072 | H25: =VLOOKUP($C25,Limits!$A$2:$B$6,2,FALSE) -> 20000 | I25: =IF(D25>H25,"OVER","OK") -> OK | J25: =IF(G25="","OK",IF(G25<F25,"BAD_DATE","OK")) -> OK
A26: CLM-0025 | B26: BR3 | C26: Travel | D26: 17752 | E26: Approved | F26: =DATE(2026,6,20) -> 46193 | G26: =DATE(2026,6,31) -> 46204 | H26: =VLOOKUP($C26,Limits!$A$2:$B$6,2,FALSE) -> 3000 | I26: =IF(D26>H26,"OVER","OK") -> OVER | J26: =IF(G26="","OK",IF(G26<F26,"BAD_DATE","OK")) -> OK
A27: CLM-0026 | B27: BR5 | C27: Travel | D27: 3159 | E27: Submitted | F27: =DATE(2026,5,20) -> 46162 | H27: =VLOOKUP($C27,Limits!$A$2:$B$6,2,FALSE) -> 3000 | I27: =IF(D27>H27,"OVER","OK") -> OVER | J27: =IF(G27="","OK",IF(G27<F27,"BAD_DATE","OK")) -> OK
A28: CLM-0027 | B28: BR4 | C28: Liability | D28: 16805 | E28: Rejected | F28: =DATE(2026,2,17) -> 46070 | H28: =VLOOKUP($C28,Limits!$A$2:$B$6,2,FALSE) -> 15000 | I28: =IF(D28>H28,"OVER","OK") -> OVER | J28: =IF(G28="","OK",IF(G28<F28,"BAD_DATE","OK")) -> OK
A29: CLM-0028 | B29: BR3 | C29: Auto | D29: 14022 | E29: Rejected | F29: =DATE(2026,2,28) -> 46081 | H29: =VLOOKUP($C29,Limits!$A$2:$B$6,2,FALSE) -> 5000 | I29: =IF(D29>H29,"OVER","OK") -> OVER | J29: =IF(G29="","OK",IF(G29<F29,"BAD_DATE","OK")) -> OK
A30: CLM-0029 | B30: BR4 | C30: Property | D30: 22881 | E30: Paid | F30: =DATE(2026,2,22) -> 46075 | G30: =DATE(2026,2,36) -> 46089 | H30: =VLOOKUP($C30,Limits!$A$2:$B$6,2,FALSE) -> 20000 | I30: =IF(D30>H30,"OVER","OK") -> OVER | J30: =IF(G30="","OK",IF(G30<F30,"BAD_DATE","OK")) -> OK
A31: CLM-0030 | B31: BR4 | C31: Travel | D31: 14640 | E31: Submitted | F31: =DATE(2026,5,18) -> 46160 | H31: =VLOOKUP($C31,Limits!$A$2:$B$6,2,FALSE) -> 3000 | I31: =IF(D31>H31,"OVER","OK") -> OVER | J31: =IF(G31="","OK",IF(G31<F31,"BAD_DATE","OK")) -> OK
A32: CLM-0031 | B32: BR4 | C32: Travel | D32: 14087 | E32: Approved | F32: =DATE(2026,3,2) -> 46083 | G32: =DATE(2026,3,26) -> 46107 | H32: =VLOOKUP($C32,Limits!$A$2:$B$6,2,FALSE) -> 3000 | I32: =IF(D32>H32,"OVER","OK") -> OVER | J32: =IF(G32="","OK",IF(G32<F32,"BAD_DATE","OK")) -> OK
A33: CLM-0032 | B33: BR5 | C33: Medical | D33: 14098 | E33: Submitted | F33: =DATE(2026,5,4) -> 46146 | H33: =VLOOKUP($C33,Limits!$A$2:$B$6,2,FALSE) -> 10000 | I33: =IF(D33>H33,"OVER","OK") -> OVER | J33: =IF(G33="","OK",IF(G33<F33,"BAD_DATE","OK")) -> OK
A34: CLM-0033 | B34: BR5 | C34: Property | D34: 7808 | E34: Rejected | F34: =DATE(2026,4,9) -> 46121 | H34: =VLOOKUP($C34,Limits!$A$2:$B$6,2,FALSE) -> 20000 | I34: =IF(D34>H34,"OVER","OK") -> OK | J34: =IF(G34="","OK",IF(G34<F34,"BAD_DATE","OK")) -> OK
A35: CLM-0034 | B35: BR3 | C35: Travel | D35: 18845 | E35: Approved | F35: =DATE(2026,2,16) -> 46069 | G35: =DATE(2026,2,34) -> 46087 | H35: =VLOOKUP($C35,Limits!$A$2:$B$6,2,FALSE) -> 3000 | I35: =IF(D35>H35,"OVER","OK") -> OVER | J35: =IF(G35="","OK",IF(G35<F35,"BAD_DATE","OK")) -> OK
A36: CLM-0035 | B36: BR3 | C36: Property | D36: 1845 | E36: Submitted | F36: =DATE(2026,1,6) -> 46028 | H36: =VLOOKUP($C36,Limits!$A$2:$B$6,2,FALSE) -> 20000 | I36: =IF(D36>H36,"OVER","OK") -> OK | J36: =IF(G36="","OK",IF(G36<F36,"BAD_DATE","OK")) -> OK
A37: CLM-0036 | B37: BR5 | C37: Auto | D37: 14195 | E37: Submitted | F37: =DATE(2026,2,1) -> 46054 | H37: =VLOOKUP($C37,Limits!$A$2:$B$6,2,FALSE) -> 5000 | I37: =IF(D37>H37,"OVER","OK") -> OVER | J37: =IF(G37="","OK",IF(G37<F37,"BAD_DATE","OK")) -> OK
A38: CLM-0037 | B38: BR2 | C38: Property | D38: 585 | E38: Rejected | F38: =DATE(2026,2,2) -> 46055 | H38: =VLOOKUP($C38,Limits!$A$2:$B$6,2,FALSE) -> 20000 | I38: =IF(D38>H38,"OVER","OK") -> OK | J38: =IF(G38="","OK",IF(G38<F38,"BAD_DATE","OK")) -> OK
A39: CLM-0038 | B39: BR2 | C39: Liability | D39: 18716 | E39: Submitted | F39: =DATE(2026,4,21) -> 46133 | H39: =VLOOKUP($C39,Limits!$A$2:$B$6,2,FALSE) -> 15000 | I39: =IF(D39>H39,"OVER","OK") -> OVER | J39: =IF(G39="","OK",IF(G39<F39,"BAD_DATE","OK")) -> OK
A40: CLM-0039 | B40: BR5 | C40: Property | D40: 12833 | E40: Paid | F40: =DATE(2026,6,6) -> 46179 | G40: =DATE(2026,6,30) -> 46203 | H40: =VLOOKUP($C40,Limits!$A$2:$B$6,2,FALSE) -> 20000 | I40: =IF(D40>H40,"OVER","OK") -> OK | J40: =IF(G40="","OK",IF(G40<F40,"BAD_DATE","OK")) -> OK
...

Sheet Limits
A1: category | B1: limit
A2: Auto | B2: 5000
A3: Property | B3: 20000
A4: Medical | B4: 10000
A5: Liability | B5: 15000
A6: Travel | B6: 3000
